<mujoco model="Legged_Robot">
  <compiler angle="radian" autolimits="true" eulerseq="zyx"/>
  <!-- <option timestep='0.001' iterations='100' solver='PGS' gravity='0 0 -9.81'>   -->
  <option  gravity='0 0 -9.81'>  
    <flag frictionloss="enable"/>
  </option>
  <size njmax="500" nconmax="100" />

  <default>
    <joint limited='true'/>
    <motor ctrllimited='true'/>
    <geom condim='1' contype="1" friction='0.6 0.2 0.2'/>
    <default class='leg_joint_param'>
      <joint damping="0.5" frictionloss="0.01" armature="0.01"/>
    </default>
    <default class="foot_collision">
      <geom type="sphere" size="0.02" condim="6" friction="10.0 0.05 0.01"/> 
    </default>
  </default>

  <asset>
    <hfield name="terrain" nrow="100" ncol="100" size="50 50 0.5 0.1"/>
    <mesh name="base_link" file="meshes/base_link.STL"/>
    <mesh name="LF_HipA_link" file="meshes/LF_HipA_link.STL"/>
    <mesh name="LF_HipF_link" file="meshes/LF_HipF_link.STL"/>
    <mesh name="LF_Knee_link" file="meshes/LF_Knee_link.STL"/>
    <mesh name="LF_Foot_link" file="meshes/LF_Foot_link.STL"/>
    <mesh name="LR_HipA_link" file="meshes/LR_HipA_link.STL"/>
    <mesh name="LR_HipF_link" file="meshes/LR_HipF_link.STL"/>
    <mesh name="LR_Knee_link" file="meshes/LR_Knee_link.STL"/>
    <mesh name="LR_Foot_link" file="meshes/LR_Foot_link.STL"/>
    <mesh name="RF_HipA_link" file="meshes/RF_HipA_link.STL"/>
    <mesh name="RF_HipF_link" file="meshes/RF_HipF_link.STL"/>
    <mesh name="RF_Knee_link" file="meshes/RF_Knee_link.STL"/>
    <mesh name="RF_Foot_link" file="meshes/RF_Foot_link.STL"/>
    <mesh name="RR_HipA_link" file="meshes/RR_HipA_link.STL"/>
    <mesh name="RR_HipF_link" file="meshes/RR_HipF_link.STL"/>
    <mesh name="RR_Knee_link" file="meshes/RR_Knee_link.STL"/>
    <mesh name="RR_Foot_link" file="meshes/RR_Foot_link.STL"/>

    <material name="matplane" reflectance="0.3" texture="texplane" texrepeat="1 1" texuniform="true"/>
    <texture name="texplane" type="2d" builtin="checker" rgb1=".2 .3 .4" rgb2=".1 0.15 0.2" width="512" height="512"/>
  </asset>

  <worldbody>
    <light directional="true" diffuse=".4 .4 .4" pos="0 0 5.0" dir="0 0 -1"/>
    <!-- <geom name="floor" type="hfield" hfield="terrain" pos="0 0 0" material="matplane" condim="3" friction="1.0 0.2 0.2" /> -->
    <geom name="floor" type="plane" size="50 50 0.1" pos="0 0 0" material="matplane" condim="3" friction="1.0 0.2 0.2" />

    <body name="base_link" pos="0 0 0.28">
      <freejoint name="floating_base"/>
      <inertial pos="0.003073 -0.000011 0.058211" mass="5.2764368" fullinertia="0.0328421 0.1037622 0.1165384 0.0000334 -0.0072546 0.0000334"/>
      
      <site name='imu' size='0.01' pos='0 0 0'/>
      <geom type="mesh" mesh="base_link" rgba="0.75 0.75 0.75 1" contype="0" conaffinity="0" group="1"/>
      <geom type="mesh" mesh="base_link" rgba="0.75 0.75 0.75 1" contype="0" conaffinity="0" group="1"/>

      <body name="LF_HipA_link" pos="0.16 0.0675 0.063" quat="0.5 0.5 0.5 0.5">
        <inertial pos="0.002621 0.000052 0.046852" mass="0.452382" fullinertia="0.0005587 0.000347 0.000309 0.0000003 -0.0000007 -0.0000001"/>
        <joint name="LF_HipA_joint" axis="0 0 1" range="-0.7853982 0.7853982" class="leg_joint_param"/>
        <geom type="mesh" mesh="LF_HipA_link"/>
        
        <body name="LF_HipF_link" pos="0.018 0 0.048" quat="0.707 0 0.707 0">
          <inertial pos="0.033261 -0.016881 0.050217" mass="0.779164" fullinertia="0.0015974 0.0032684 0.0043304 0.0015051 -0.0004429 0.0002247"/>
          <joint name="LF_HipF_joint" axis="0 0 1" range="-1.2217658 0.8726683" class="leg_joint_param"/>
          <geom type="mesh" mesh="LF_HipF_link"/>
          
          <body name="LF_Knee_link" pos="0.1707 -0.1222 0.05">
            <inertial pos="-0.055107 -0.080197 0.016515" mass="0.121558" fullinertia="0.0005493 0.0002237 0.0007696 -0.0003334 -0.0000001 -0.0000002"/>
            <joint name="LF_Knee_joint" axis="0 0 1" range="-1.2217299 0.69813" class="leg_joint_param"/>
            <geom type="mesh" mesh="LF_Knee_link"/>
            <site name="LF_foot_site" pos="-0.11 -0.19 0.016" size="0.01"/>
            
            <geom name="LF_foot_visual" type="mesh" mesh="LF_Foot_link" pos="-0.11 -0.19 0.016" quat="0 0 0.707 0.707" 
                  contype="0" conaffinity="0" group="1" material="matplane"/> 
            <geom name="LF_foot_collision" class="foot_collision" pos="-0.11 -0.19 0.016" rgba="0 0 0 0"/>
          </body>
        </body>
      </body>

      <body name="LR_HipA_link" pos="-0.16 0.0675 0.063" quat="0.5 0.5 -0.5 -0.5">
        <inertial pos="-0.002621 -0.000052 0.046852" mass="0.452382" fullinertia="0.0005587 0.000347 0.000309 0.0000003 0.0000007 0.0000001"/>
        <joint name="LR_HipA_joint" axis="0 0 1" range="-0.7853982 0.7853982" class="leg_joint_param"/>
        <geom type="mesh" mesh="LR_HipA_link"/>
        
        <body name="LR_HipF_link" pos="-0.018 0 0.048" quat="0.707 0 -0.707 0">
          <inertial pos="0.03326 -0.016881 0.050217" mass="0.779164" fullinertia="0.0015974 0.0032684 0.0043304 0.0015051 -0.0004429 0.0002247"/>
          <joint name="LR_HipF_joint" axis="0 0 1" range="-1.2217305 0.8726683" class="leg_joint_param"/>
          <geom type="mesh" mesh="LR_HipF_link"/>
          
          <body name="LR_Knee_link" pos="0.1707 -0.1222 0.05">
            <inertial pos="-0.055107 -0.080197 0.016515" mass="0.121558" fullinertia="0.0005493 0.0002237 0.0007696 -0.0003334 -0.0000001 -0.0000002"/>
            <joint name="LR_Knee_joint" axis="0 0 1" range="-1.2217299 0.69813" class="leg_joint_param"/>
            <geom type="mesh" mesh="LR_Knee_link"/>
            <site name="LR_foot_site" pos="-0.11 -0.19 0.016" size="0.01"/>

            <geom name="LR_foot_visual" type="mesh" mesh="LR_Foot_link" pos="-0.11 -0.19 0.016" quat="0 0 -0.707 -0.707" 
                  contype="0" conaffinity="0" group="1" material="matplane"/>
            <geom name="LR_foot_collision" class="foot_collision" pos="-0.11 -0.19 0.016" rgba="0 0 0 0"/>
          </body>
        </body>
      </body>

      <body name="RF_HipA_link" pos="0.16 -0.0675 0.063" quat="0.5 0.5 0.5 0.5">
        <inertial pos="-0.002621 -0.000052 0.046852" mass="0.452382" fullinertia="0.0005587 0.000347 0.000309 0.0000003 0.0000007 0.0000001"/>
        <joint name="RF_HipA_joint" axis="0 0 1" range="-0.7853982 0.7853982" class="leg_joint_param"/>
        <geom type="mesh" mesh="RF_HipA_link"/>
        
        <body name="RF_HipF_link" pos="-0.018 0 0.048" quat="0.707 0 -0.707 0">
          <inertial pos="-0.033247 -0.016939 0.050217" mass="0.779164" fullinertia="0.0015958 0.0032692 0.0043296 -0.0015036 0.0004432 0.0002236"/>
          <joint name="RF_HipF_joint" axis="0 0 1" range="-0.8726999 1.2217342" class="leg_joint_param"/>
          <geom type="mesh" mesh="RF_HipF_link"/>
          
          <body name="RF_Knee_link" pos="-0.1707 -0.1222 0.05">
            <inertial pos="0.055107 -0.080197 0.016485" mass="0.121558" fullinertia="0.0005493 0.0002237 0.0007696 0.0003334 -0.0000001 0.0000002"/>
            <joint name="RF_Knee_joint" axis="0 0 1" range="-0.6981312 1.2217287" class="leg_joint_param"/>
            <geom type="mesh" mesh="RF_Knee_link"/>
            <site name="RF_foot_site" pos="0.11 -0.19 0.016" size="0.01"/>

            <geom name="RF_foot_visual" type="mesh" mesh="RF_Foot_link" pos="0.11 -0.19 0.016" quat="0.707 -0.707 0 0" 
                  contype="0" conaffinity="0" group="1" material="matplane"/>
            <geom name="RF_foot_collision" class="foot_collision" pos="0.11 -0.19 0.016" rgba="0 0 0 0"/>
          </body>
        </body>
      </body>

      <body name="RR_HipA_link" pos="-0.16 -0.0675 0.063" quat="0.5 0.5 -0.5 -0.5">
        <inertial pos="0.002621 0.000052 0.046852" mass="0.452382" fullinertia="0.0005587 0.000347 0.000309 0.0000003 -0.0000007 -0.0000001"/>
        <joint name="RR_HipA_joint" axis="0 0 1" range="-0.7853982 0.7853982" class="leg_joint_param"/>
        <geom type="mesh" mesh="RR_HipA_link"/>
        
        <body name="RR_HipF_link" pos="0.018 0 0.048" quat="0.707 0 0.707 0">
          <inertial pos="-0.033246 -0.01694 0.050217" mass="0.779164" fullinertia="0.0015958 0.0032692 0.0043296 -0.0015036 0.0004432 0.0002236"/>
          <joint name="RR_HipF_joint" axis="0 0 1" range="-0.8726999 1.2217305" class="leg_joint_param"/>
          <geom type="mesh" mesh="RR_HipF_link"/>
          
          <body name="RR_Knee_link" pos="-0.1707 -0.1222 0.05">
            <inertial pos="0.055107 -0.080197 0.016485" mass="0.121558" fullinertia="0.0005493 0.0002237 0.0007696 0.0003334 -0.0000001 0.0000002"/>
            <joint name="RR_Knee_joint" axis="0 0 1" range="-0.6981312 1.2217287" class="leg_joint_param"/>
            <geom type="mesh" mesh="RR_Knee_link"/>
            <site name="RR_foot_site" pos="0.11 -0.19 0.016" size="0.01"/>

            <geom name="RR_foot_visual" type="mesh" mesh="RR_Foot_link" pos="0.11 -0.19 0.016" quat="0.707 -0.707 0 0" 
                  contype="0" conaffinity="0" group="1" material="matplane"/>
            <geom name="RR_foot_collision" class="foot_collision" pos="0.11 -0.19 0.016" rgba="0 0 0 0"/>
          </body>
        </body>
      </body>
    </body> 
  </worldbody>

  <actuator>
    <motor name="LF_HipA" joint="LF_HipA_joint" gear="1" ctrllimited="true" ctrlrange="-17 17"/>
    <motor name="LF_HipF" joint="LF_HipF_joint" gear="1" ctrllimited="true" ctrlrange="-17 17"/>
    <motor name="LF_Knee" joint="LF_Knee_joint" gear="1" ctrllimited="true" ctrlrange="-25 25"/>

    <motor name="LR_HipA" joint="LR_HipA_joint" gear="1" ctrllimited="true" ctrlrange="-17 17"/>
    <motor name="LR_HipF" joint="LR_HipF_joint" gear="1" ctrllimited="true" ctrlrange="-17 17"/>
    <motor name="LR_Knee" joint="LR_Knee_joint" gear="1" ctrllimited="true" ctrlrange="-25 25"/>

    <motor name="RF_HipA" joint="RF_HipA_joint" gear="1" ctrllimited="true" ctrlrange="-17 17"/>
    <motor name="RF_HipF" joint="RF_HipF_joint" gear="1" ctrllimited="true" ctrlrange="-17 17"/>
    <motor name="RF_Knee" joint="RF_Knee_joint" gear="1" ctrllimited="true" ctrlrange="-25 25"/>

    <motor name="RR_HipA" joint="RR_HipA_joint" gear="1" ctrllimited="true" ctrlrange="-17 17"/>
    <motor name="RR_HipF" joint="RR_HipF_joint" gear="1" ctrllimited="true" ctrlrange="-17 17"/>
    <motor name="RR_Knee" joint="RR_Knee_joint" gear="1" ctrllimited="true" ctrlrange="-25 25"/>
  </actuator>

  <sensor>
    <framequat name="orientation" objtype="site" objname="imu" noise="0.001"/>
    <framepos name="position" objtype="site" objname="imu" noise="0.001"/>
    <gyro name="angular-velocity" site="imu" noise="0.005"/>
    <velocimeter name="linear-velocity" site="imu" noise="0.001"/>
    <accelerometer name="linear-acceleration" site="imu" noise="0.005"/>
    <touch name="LF_touch" site="LF_foot_site"/>
    <touch name="LR_touch" site="LR_foot_site"/>
    <touch name="RF_touch" site="RF_foot_site"/>
    <touch name="RR_touch" site="RR_foot_site"/>
  </sensor>
</mujoco>

  <!-- <default>
    <joint limited='true'/>
    <motor ctrllimited='true'/>
    <geom condim='4' contype="1" conaffinity="15" solref='0.001 2' friction='0.9 0.2 0.2'/>
    <default class='leg_joint_param'>
      <joint damping="0.5" frictionloss="0.01" armature="0.01"/>
    </default>
  </default> -->

  <!-- <default>
    <joint limited='true'/>
    <motor ctrllimited='true'/>
    <geom condim='4' contype="1" conaffinity="15" solref='0.001 2' friction='0.9 0.2 0.2'/>
    <default class='leg_joint_param'>
      <joint damping="0.5" frictionloss="0.01" armature="0.01"/>
    </default>
    <default class="foot_collision">
      <geom type="sphere" size="0.02" condim="6" friction="1.0 0.05 0.01" solimp="0.9 0.95 0.001" solref="0.005 1"/>
    </default>
  </default> -->


  <!-- <actuator>
    <position name="LF_HipA" joint="LF_HipA_joint" kp="25" kv="0.5" forcerange="-17 17" ctrlrange="-0.7853982 0.7853982"/>
    <position name="LF_HipF" joint="LF_HipF_joint" kp="25" kv="0.5" forcerange="-17 17" ctrlrange="-1.2217658 0.8726683"/>
    <position name="LF_Knee" joint="LF_Knee_joint" kp="25" kv="0.5" forcerange="-25 25" ctrlrange="-1.2217299 0.69813"/>

    <position name="LR_HipA" joint="LR_HipA_joint" kp="25" kv="0.5" forcerange="-17 17" ctrlrange="-0.7853982 0.7853982"/>
    <position name="LR_HipF" joint="LR_HipF_joint" kp="25" kv="0.5" forcerange="-17 17" ctrlrange="-1.2217305 0.8726683"/>
    <position name="LR_Knee" joint="LR_Knee_joint" kp="25" kv="0.5" forcerange="-25 25" ctrlrange="-1.2217299 0.69813"/>

    <position name="RF_HipA" joint="RF_HipA_joint" kp="25" kv="0.5" forcerange="-17 17" ctrlrange="-0.7853982 0.7853982"/>
    <position name="RF_HipF" joint="RF_HipF_joint" kp="25" kv="0.5" forcerange="-17 17" ctrlrange="-0.8726999 1.2217342"/>
    <position name="RF_Knee" joint="RF_Knee_joint" kp="25" kv="0.5" forcerange="-25 25" ctrlrange="-0.6981312 1.2217287"/>

    <position name="RR_HipA" joint="RR_HipA_joint" kp="25" kv="0.5" forcerange="-17 17" ctrlrange="-0.7853982 0.7853982"/>
    <position name="RR_HipF" joint="RR_HipF_joint" kp="25" kv="0.5" forcerange="-17 17" ctrlrange="-0.8726999 1.2217305"/>
    <position name="RR_Knee" joint="RR_Knee_joint" kp="25" kv="0.5" forcerange="-25 25" ctrlrange="-0.6981312 1.2217287"/>
  </actuator> -->